Workbook
Name SegmentaçãodeDados_Taxa: #N/A

Sheet DIN_For
A3: Sum of Pago | B3: Rótulos de Coluna
B4: 2025 | C4: 2026 | H4: 2026 Total | I4: (vazio) | J4: (vazio) Total | K4: Total Geral
C5: jan | D5: fev | E5: mar | F5: abr | G5: mai | I5: <02/01/2025
A6: Rótulos de Linha
A7: ITAU UNIBANCO S.A. | B7: 392933.77 | C7: 29305.32 | D7: 28000.93 | E7: 28015.73 | F7: 25593.32 | G7: 23816.56 | H7: 134731.86 | K7: 527665.63
A8: FORTE DA GRANJA EMPREENDIMENTO IMOBILIARIO LTDA | B8: 347873.16 | C8: 27343.18 | D8: 27343.18 | E8: 25123.8 | F8: 28087.8 | G8: 28087.8 | H8: 135985.76 | K8: 483858.92
A9: MINISTERIO DA FAZENDA | B9: 248831.74 | C9: 20778.97 | D9: 18546.78 | E9: 19708.53 | F9: 18081.14 | G9: 18702.19 | H9: 95817.61 | K9: 344649.35
A10: GRAU T FRANQUIAS DE CURSOS TECNICOS LTDA. | B10: 203292.18 | C10: 10094.52 | D10: 20366.73 | E10: 17478.58 | F10: 24738.89 | G10: 23110.49 | H10: 95789.21 | K10: 299081.39
A11: EDITORA GRAU LTDA. | B11: 105519.3 | C11: 10698.66 | E11: 10702.08 | F11: 15153.55 | G11: 5350 | H11: 41904.29 | K11: 147423.59
A12: Associação Brasileira dos Franc | B12: 129034.06 | K12: 129034.06
A13: Lucia De Souza Leão Gouveia | B13: 56958.33 | C13: 12000 | D13: 12104 | E13: 12900 | F13: 12000 | G13: 12018.35 | H13: 61022.35 | K13: 117980.68
A14: FERNANDO AFONSO DOS SANTOS | B14: 64175.78 | C14: 7826.86 | D14: 9960 | E14: 9192 | F14: 9280.29 | G14: 8346 | H14: 44605.15 | K14: 108780.93
A15: Carlene Dos Santos | B15: 74988.28 | C15: 4278.62 | D15: 8150.42 | E15: 6411 | F15: 6526 | G15: 3545.62 | H15: 28911.66 | K15: 103899.94
A16: TIAGO PESSOA COSTA REIS | B16: 38460 | C16: 7266 | D16: 10346.72 | E16: 10346.72 | F16: 10346.72 | G16: 10346.72 | H16: 48652.88 | K16: 87112.88
A17: NIVEL A FRANQUIAS DE CURSOS DE FORMACAO PROFISSIONAL LTDA | B17: 48941.16 | C17: 7809.73 | D17: 8325.78 | E17: 7183.96 | F17: 8386.69 | G17: 6319.52 | H17: 38025.68 | K17: 86966.84
A18: FLASH BENEFICIOS - VT E VA | B18: 58623.34 | C18: 9468.6 | D18: 4384.28 | F18: 7583.57 | H18: 21436.45 | K18: 80059.79
A19: FACEBOOK SERVICOS ONLINE DO BR | B19: 46556.02 | C19: 6480.36 | D19: 7496.21 | E19: 7937 | F19: 4857.42 | G19: 4600 | H19: 31370.99 | K19: 77927.01
A20: FLASH TECNOLOGIA E INSTITUICAO DE PAGAMENTO LTDA | B20: 65379.81 | K20: 65379.81
A21: Thayna Cristine | B21: 40709.89 | C21: 4026.22 | D21: 5244.22 | E21: 7183.59 | F21: 3939.58 | G21: 3678.94 | H21: 24072.55 | K21: 64782.44
A22: FGTS - Fundo de garantia do tempo de serviço | B22: 34858.4 | C22: 6136.33 | D22: 4717.62 | E22: 4586.75 | F22: 5505.75 | G22: 1638.17 | H22: 22584.62 | K22: 57443.02
A23: Atacama Digital | B23: 51744.79 | K23: 51744.79
A24: Weslley Mateus Da Silva | B24: 30885.74 | C24: 2843 | D24: 4459.42 | E24: 4699.42 | F24: 4031 | G24: 4166.58 | H24: 20199.42 | K24: 51085.16
A25: Elisangela Da Silva Munarão | B25: 46068.87 | D25: 285.42 | H25: 285.42 | K25: 46354.29
A26: MACIEL BATISTA DE OLIVEIRA | B26: 27760 | C26: 2280 | D26: 3136 | E26: 2904 | F26: 5311 | G26: 3894 | H26: 17525 | K26: 45285
A27: EDSON JOSE DE MELO | B27: 26550.85 | C27: 2371 | D27: 4403.42 | E27: 4317.97 | F27: 4164.9 | G27: 3469.26 | H27: 18726.55 | K27: 45277.4
A28: Maria Sandra Santos Tavares | B28: 31360 | C28: 2260 | D28: 2940 | E28: 1932 | F28: 3128 | G28: 3592 | H28: 13852 | K28: 45212
A29: Google internet ltda | B29: 34245.02 | C29: 3514.58 | D29: 2498.73 | E29: 2058 | F29: 1197.9 | G29: 900 | H29: 10169.21 | K29: 44414.23
A30: Ana Beatriz Faustino Lopes | B30: 31742.46 | C30: 2980 | D30: 2720 | F30: 980 | G30: 3668 | H30: 10348 | K30: 42090.46
A31: Adriana da Silva Furlan | B31: 27564.52 | C31: 2539.1 | D31: 2638.02 | E31: 2916.02 | F31: 2622 | G31: 3123.42 | H31: 13838.56 | K31: 41403.08
A32: Marcilene de Jesus Duarte | B32: 27818.18 | C32: 4526.11 | D32: 1752.82 | E32: 1811.42 | F32: 2570.42 | G32: 2621.42 | H32: 13282.19 | K32: 41100.37
A33: ANE CAROLINA ARAUJO | B33: 30532.96 | C33: 1259 | D33: 1834.86 | E33: 970 | F33: 3353 | G33: 2202.62 | H33: 9619.48 | K33: 40152.44
A34: Elo camisetas Ltda | B34: 26337.78 | E34: 3179.78 | F34: 3192.21 | G34: 4944.5 | H34: 11316.49 | K34: 37654.27
A35: Kaio Felix de Macedo | B35: 22585.44 | C35: 2731 | D35: 2077.42 | E35: 3349.67 | F35: 2424 | G35: 4295.62 | H35: 14877.71 | K35: 37463.15
A36: Enel | B36: 14210.22 | C36: 4397.03 | D36: 4584.44 | E36: 4693.61 | F36: 4100.17 | G36: 5096.29 | H36: 22871.54 | K36: 37081.76
A37: Associação Brasileira dos Franc /NIVEL A | C37: 983.63 | D37: 8490.92 | E37: 7896.85 | F37: 9304.76 | G37: 10307.18 | H37: 36983.34 | K37: 36983.34
A38: QUALINFO SERVICOS DE INFORMATICA LTDA | B38: 23394.29 | C38: 1846.4 | D38: 1883.42 | E38: 1846.4 | F38: 1846.4 | G38: 1883.42 | H38: 9306.04 | K38: 32700.33
A39: João Victor Santos Costa | B39: 16669.69 | C39: 2772 | D39: 2898.38 | E39: 3396.14 | F39: 3001 | G39: 3523.1 | H39: 15590.62 | K39: 32260.31
A40: Cristina Pereira de Sena | B40: 21439.72 | C40: 1347 | D40: 1558.42 | E40: 1781.62 | F40: 2784.71 | G40: 499.02 | H40: 7970.77 | K40: 29410.49
A41: LETICIA NUNES DA FONSECA | B41: 20168.94 | C41: 1834.9 | D41: 495.42 | E41: 2076.83 | F41: 1816 | G41: 2577.86 | H41: 8801.01 | K41: 28969.95
A42: ELIANE FREIRES NEMET MARTINS | B42: 15220 | C42: 2160 | E42: 640 | F42: 5968 | G42: 4944 | H42: 13712 | K42: 28932
...

Sheet DIN_TAXA
A10: Sum of Pago | B10: Rótulos de Coluna
B11: 2025 | C11: 2026 | H11: 2026 Total | I11: (vazio) | J11: (vazio) Total | K11: Total Geral
C12: jan | D12: fev | E12: mar | F12: abr | G12: mai | I12: <02/01/2025
A13: Rótulos de Linha
A14: 60013-SALARIOS | B14: 457872.8 | C14: 34102 | D14: 34603 | E14: 31312.18 | F14: 32955.08 | G14: 34895.88 | H14: 167868.14 | K14: 625740.94
A15: 60004-INSTRUTOR | B15: 387694.6 | C15: 22440 | D15: 32472 | E15: 25036 | F15: 37714 | G15: 33515 | H15: 151177 | K15: 538871.6
A16: 60040-ALUGUEL | B16: 348243.16 | C16: 27343.18 | D16: 27343.18 | E16: 25123.8 | F16: 28087.8 | G16: 28087.8 | H16: 135985.76 | K16: 484228.92
A17: 60119-SIMPLES NACIONAL | B17: 218627.46 | C17: 20778.97 | D17: 18546.78 | E17: 19708.53 | F17: 18081.14 | G17: 18702.19 | H17: 95817.61 | K17: 314445.07
A18: 60052-ROYALTIES | B18: 204499.04 | C18: 12717.54 | D18: 24839.94 | E18: 20571.58 | F18: 26432.78 | G18: 24737.21 | H18: 109299.05 | K18: 313798.09
A19: 60005-PRECEPTOR | B19: 239003.66 | C19: 12880 | D19: 9860 | E19: 13240 | F19: 16020 | G19: 17580 | H19: 69580 | K19: 308583.66
A20: 60106-JUROS E TAXAS SOBRE EMPRESTIMOS | B20: 191296.46 | C20: 19355.85 | D20: 21052.12 | E20: 21217.11 | F20: 21068.72 | G20: 20788.27 | H20: 103482.07 | K20: 294778.53
A21: 60158-CARTAO DE CREDITO | B21: 214698.17 | C21: 11777.86 | D21: 13409.63 | E21: 12597.71 | F21: 10213.05 | G21: 8683.25 | H21: 56681.5 | K21: 271379.67
A22: 60030-PREMIACOES E GRATIFICACOES | B22: 156787.6 | C22: 10121 | D22: 21688 | E22: 17749 | F22: 17470 | G22: 11303.6 | H22: 78331.6 | K22: 235119.2
A23: 60001-APOSTILA | B23: 155287.22 | C23: 15185.37 | D23: 3152.57 | E23: 12695.6 | F23: 21146.35 | G23: 9342.8 | H23: 61522.69 | K23: 216809.91
A24: 60109-MIDIA DE INTERNET | B24: 146429.73 | C24: 11910.26 | D24: 12041.64 | E24: 12000.93 | F24: 11732.48 | G24: 7546.7 | H24: 55232.01 | K24: 201661.74
A25: 60053-FUNDO DE PROPAGANDA | B25: 133255.14 | C25: 11568.26 | D25: 11802.77 | E25: 12392.42 | F25: 9304.76 | G25: 13742.91 | H25: 58811.12 | K25: 192066.26
... A31: 60159-CONTRA PARTIDA DE ESTAGIO | B31: 35102.06 | C31: 3227.5 | D31: 3527.5 | E31: 9830.59 | F31: 10279.2 | G31: 4055 | H31: 30919.79 | K31: 66021.85
A32: 60067-OUTRAS DESPESAS | B32: 58430.23 | C32: 1413.36 | D32: 405.87 | F32: 524.29 | H32: 2343.52 | K32: 60773.75
A33: 60018-FGTS SALARIO | B33: 34584.1 | C33: 5776.39 | D33: 4717.62 | E33: 4586.75 | F33: 4640.87 | G33: 1473.02 | H33: 21194.65 | K33: 55778.75
A34: 60069-JURIDICO | B34: 21113.06 | C34: 1621 | D34: 9827.92 | E34: 2154.49 | F34: 12509.06 | G34: 3601.34 | H34: 29713.81 | K34: 50826.87
A35: 60003-FARDAMENTO ALUNOS | B35: 31634.47 | C35: 1996.8 | D35: 1567 | E35: 4003.78 | F35: 4646.21 | G35: 5808.67 | H35: 18022.46 | K35: 49656.93
A36: 60047-MANUTENCAO PREDIAL | B36: 23989.36 | C36: 6327 | D36: 4782.58 | E36: 3910.29 | F36: 3708.68 | G36: 4076.43 | H36: 22804.98 | K36: 46794.34
A37: 60098-TARIFAS BANCARIAS | B37: 21692.02 | C37: 4883.76 | D37: 3885.9 | E37: 4547.63 | F37: 4658.27 | G37: 4691.76 | H37: 22667.32 | K37: 44359.34
A38: 60019-RESCISOES / IDENIZACOES | B38: 32648.08 | C38: 1016.14 | D38: 11.26 | E38: 6281.17 | F38: 1600.17 | G38: 2002.16 | H38: 10910.9 | K38: 43558.98
A39: 60017-INSS SALARIO | B39: 29811.73 | C39: 2587.6 | D39: 2614.42 | E39: 2531.11 | F39: 2783.83 | G39: 3101.82 | H39: 13618.78 | K39: 43430.51
A40: 60042-ENERGIA ELETRICA | B40: 14240.77 | C40: 4397.03 | D40: 4645.44 | E40: 4693.61 | F40: 4100.17 | G40: 5096.29 | H40: 22932.54 | K40: 37173.31
A41: 60043-AGUA E ESGOTO | B41: 24046.7 | C41: 2250.53 | D41: 1027.31 | E41: 2455.92 | F41: 1757.08 | G41: 2516.22 | H41: 10007.06 | K41: 34053.76
A42: 60014-FERIAS | B42: 20534.02 | C42: 2243.96 | D42: 1000 | E42: 3318 | F42: 1726.91 | G42: 2245.5 | H42: 10534.37 | K42: 31068.39
A43: 60015-13º SALARIO | B43: 29574.85 | K43: 29574.85
A44: 60068-CONTABILIDADE | B44: 18198.79 | C44: 3060.22 | D44: 1621 | E44: 1628.5 | F44: 1646 | G44: 1621 | H44: 9576.72 | K44: 27775.51
A45: 60027-AJUDA DE CUSTOS PESSOAL | B45: 13980.74 | C45: 1500 | D45: 2535.42 | E45: 1792 | F45: 1859.64 | G45: 1980 | H45: 9667.06 | K45: 23647.8
A46: 60057-MATERIAL DE LIMPEZA E CONSERVACAO | B46: 12129.63 | C46: 1721.21 | D46: 1708.28 | E46: 188.61 | F46: 1818.99 | G46: 2094.25 | H46: 7531.34 | K46: 19660.97
A47: 60078-LOCACAO DE EQUIPAMENTOS | B47: 14960.22 | C47: 390 | D47: 431.59 | E47: 390 | F47: 233.3 | G47: 1174.19 | H47: 2619.08 | K47: 17579.3
A48: 60020-FGTS RESCISORIO | B48: 11898.64 | C48: 2707.76 | E48: 1125.59 | F48: 864.88 | G48: 165.15 | H48: 4863.38 | K48: 16762.02
A49: 60084-OUTRAS CONSULTORIAS | B49: 333 | C49: 2333 | D49: 3331 | E49: 3841.22 | F49: 3044.73 | G49: 3770 | H49: 16319.95 | K49: 16652.95
A50: 60083-TRANSPORTES E FRETES | B50: 9949.81 | C50: 957.55 | D50: 1679.83 | E50: 1000.46 | F50: 1480.37 | G50: 1338.72 | H50: 6456.93 | K50: 16406.74
A51: 60081-SERVICO TECNOLOGIA DA INFORMACAO | B51: 10051 | C51: 900 | D51: 900 | E51: 900 | F51: 900 | G51: 900 | H51: 4500 | K51: 14551
A52: 60049-MANUTENCAO DE EQUIPAMENTOS | B52: 12590.74 | D52: 180 | E52: 99 | F52: 500 | H52: 779 | K52: 13369.74
A53: 60010-DEVOLUCAO DE PARCELAS | B53: 11065.5 | D53: 297.5 | E53: 39.84 | F53: 75 | G53: 11 | H53: 423.34 | K53: 11488.84
A54: 60058-MATERIAL DE USO E CONSUMO | B54: 6524.04 | C54: 485.02 | D54: 108.49 | E54: 1322.35 | F54: 826.86 | G54: 668.27 | H54: 3410.99 | K54: 9935.03
...

Sheet BASE
A1: Matrícula | B1: Nome | C1: Taxa | D1: Mês/Ano | E1: Vencimento | F1: Data Baixa | G1: Valor | H1: Juros | I1: Multa | J1: Desconto | K1: Pago | L1: Forma | M1: ANo
A2: 00024 | B2: Google internet ltda | C2: 60109-MIDIA DE INTERNET | D2: 01/2025 | E2: 45659 | F2: 45659 | G2: 1000 | H2: 0 | I2: 0 | J2: 0 | K2: 1000 | L2: Dinheiro | M2: =YEAR(F2) -> 2025
A3: 00248 | B3: Jennifer Franklin Barbosa | C3: 60023-VALE TRANSPORTE | D3: 01/2025 | E3: 45659 | F3: 45659 | G3: 183.6 | H3: 0 | I3: 0 | J3: 0 | K3: 183.6 | L3: Dinheiro | M3: =YEAR(F3) -> 2025
A4: 00315 | B4: HELMA DE SOUSA | C4: 60023-VALE TRANSPORTE | D4: 01/2025 | E4: 45659 | F4: 45659 | G4: 63.6 | H4: 0 | I4: 0 | J4: 0 | K4: 63.6 | L4: Dinheiro | M4: =YEAR(F4) -> 2025
A5: 00193 | B5: FACEBOOK SERVICOS ONLINE DO BR | C5: 60109-MIDIA DE INTERNET | D5: 01/2025 | E5: 45659 | F5: 45659 | G5: 1000 | H5: 0 | I5: 0 | J5: 0 | K5: 1000 | L5: Dinheiro | M5: =YEAR(F5) -> 2025
A6: 00193 | B6: FACEBOOK SERVICOS ONLINE DO BR | C6: 60109-MIDIA DE INTERNET | D6: 01/2025 | E6: 45659 | F6: 45659 | G6: 2288.3 | H6: 0 | I6: 0 | J6: 0 | K6: 2288.3 | L6: Dinheiro | M6: =YEAR(F6) -> 2025
A7: 00024 | B7: Google internet ltda | C7: 60109-MIDIA DE INTERNET | D7: 01/2025 | E7: 45659 | F7: 45659 | G7: 1211.7 | H7: 0 | I7: 0 | J7: 0 | K7: 1211.7 | L7: Dinheiro | M7: =YEAR(F7) -> 2025
A8: 00377 | B8: VIACAO OSASCO LTDA | C8: 60023-VALE TRANSPORTE | D8: 01/2025 | E8: 45659 | F8: 45659 | G8: 165.8 | H8: 0 | I8: 0 | J8: 0 | K8: 165.8 | L8: Dinheiro | M8: =YEAR(F8) -> 2025
A9: 00083 | B9: FLASH BENEFICIOS - VT E VA | C9: 60023-VALE TRANSPORTE | D9: 01/2025 | E9: 45659 | F9: 45659 | G9: 2737.9 | H9: 0 | I9: 0 | J9: 0 | K9: 2737.9 | L9: Dinheiro | M9: =YEAR(F9) -> 2025
A10: 00106 | B10: ALLDIX INFORMATICA LTDA | C10: 60049-MANUTENCAO DE EQUIPAMENTOS | D10: 01/2025 | E10: 45659 | F10: 45659 | G10: 900 | H10: 0 | I10: 0 | J10: 0 | K10: 900 | L10: Dinheiro | M10: =YEAR(F10) -> 2025
A11: 00362 | B11: ITAU UNIBANCO S.A. | C11: 60098-TARIFAS BANCARIAS | D11: 01/2025 | E11: 45660 | F11: 45660 | G11: 1.79 | H11: 0 | I11: 0 | J11: 0 | K11: 1.79 | L11: Dinheiro | M11: =YEAR(F11) -> 2025
A12: 00362 | B12: ITAU UNIBANCO S.A. | C12: 60102-IOF | D12: 01/2025 | E12: 45660 | F12: 45660 | G12: 93.66 | H12: 0 | I12: 0 | J12: 0 | K12: 93.66 | L12: Dinheiro | M12: =YEAR(F12) -> 2025
A13: 00131 | B13: Lorenna Nascimento Santos | C13: 60032-EXAMES MEDICOS / PCMSO / PPRA | D13: 01/2025 | E13: 45660 | F13: 45660 | G13: 30 | H13: 0 | I13: 0 | J13: 0 | K13: 30 | L13: Dinheiro | M13: =YEAR(F13) -> 2025
... A3624: 00316 | B3624: ANE CAROLINA ARAUJO | C3624: 60014-FERIAS | D3624: 12/2025 | E3624: 46009 | F3624: 46009 | G3624: 2245.16 | H3624: 0 | I3624: 0 | J3624: 0 | K3624: 2245.16 | L3624: Dinheiro | M3624: =YEAR(F3624) -> 2025
A3625: 668 | B3625: 62.254.936 SAMIR FARAH | C3625: 60084-OUTRAS CONSULTORIAS | D3625: 45992 | E3625: 46010 | F3625: 46010 | G3625: 333 | H3625: 0 | I3625: 0 | J3625: 0 | K3625: 333 | L3625: Dinheiro | M3625: =YEAR(F3625) -> 2025
A3626: 00351 | B3626: Adriana da Silva Furlan | C3626: 60015-13º SALARIO | D3626: 12/2025 | E3626: 46010 | F3626: 46010 | G3626: 580 | H3626: 0 | I3626: 0 | J3626: 0 | K3626: 580 | L3626: Dinheiro | M3626: =YEAR(F3626) -> 2025
A3627: 00349 | B3627: Marcilene de Jesus Duarte | C3627: 60015-13º SALARIO | D3627: 12/2025 | E3627: 46010 | F3627: 46010 | G3627: 516 | H3627: 0 | I3627: 0 | J3627: 0 | K3627: 516 | L3627: Dinheiro | M3627: =YEAR(F3627) -> 2025
A3628: 00160 | B3628: Cristina Pereira de Sena | C3628: 60015-13º SALARIO | D3628: 12/2025 | E3628: 46010 | F3628: 46010 | G3628: 770 | H3628: 0 | I3628: 0 | J3628: 0 | K3628: 770 | L3628: Dinheiro | M3628: =YEAR(F3628) -> 2025
A3629: 00416 | B3629: Atila Gandhi | C3629: 60015-13º SALARIO | D3629: 12/2025 | E3629: 46010 | F3629: 46010 | G3629: 580 | H3629: 0 | I3629: 0 | J3629: 0 | K3629: 580 | L3629: Dinheiro | M3629: =YEAR(F3629) -> 2025
A3630: 00104 | B3630: DARF | C3630: 60017-INSS SALARIO | D3630: 12/2025 | E3630: 46010 | F3630: 46010 | G3630: 2506.22 | H3630: 0 | I3630: 0 | J3630: 0 | K3630: 2506.22 | L3630: Dinheiro | M3630: =YEAR(F3630) -> 2025
A3631: 00104 | B3631: DARF | C3631: 60017-INSS SALARIO | D3631: 12/2025 | E3631: 46010 | F3631: 46010 | G3631: 2340.96 | H3631: 0 | I3631: 0 | J3631: 0 | K3631: 2340.96 | L3631: Dinheiro | M3631: =YEAR(F3631) -> 2025
A3632: 00104 | B3632: DARF | C3632: 60016-IRRF SALARIO | D3632: 12/2025 | E3632: 46010 | F3632: 46010 | G3632: 74.48 | H3632: 0 | I3632: 0 | J3632: 0 | K3632: 74.48 | L3632: Dinheiro | M3632: =YEAR(F3632) -> 2025
A3633: 00072 | B3633: MINISTERIO DA FAZENDA | C3633: 60119-SIMPLES NACIONAL | D3633: 12/2025 | E3633: 46010 | F3633: 46010 | G3633: 14220.97 | H3633: 0 | I3633: 0 | J3633: 0 | K3633: 14220.97 | L3633: Dinheiro | M3633: =YEAR(F3633) -> 2025
A3634: 00364 | B3634: Naiara Oliveira Rodrigues | C3634: 60015-13º SALARIO | D3634: 12/2025 | E3634: 46010 | F3634: 46010 | G3634: 645 | H3634: 0 | I3634: 0 | J3634: 0 | K3634: 645 | L3634: Dinheiro | M3634: =YEAR(F3634) -> 2025
A3635: 00291 | B3635: Noberto da Silva Ferreira | C3635: 60015-13º SALARIO | D3635: 12/2025 | E3635: 46010 | F3635: 46010 | G3635: 65 | H3635: 0 | I3635: 0 | J3635: 0 | K3635: 65 | L3635: Dinheiro | M3635: =YEAR(F3635) -> 2025
A3636: 00606 | B3636: Priscila de Jesus dos Santos ferreira | C3636: 60015-13º SALARIO | D3636: 12/2025 | E3636: 46010 | F3636: 46010 | G3636: 194 | H3636: 0 | I3636: 0 | J3636: 0 | K3636: 194 | L3636: Dinheiro | M3636: =YEAR(F3636) -> 2025
A3637: 00511 | B3637: Ricardo da Silva Lino | C3637: 60015-13º SALARIO | D3637: 12/2025 | E3637: 46010 | F3637: 46010 | G3637: 638 | H3637: 0 | I3637: 0 | J3637: 0 | K3637: 638 | L3637: Dinheiro | M3637: =YEAR(F3637) -> 2025
... A3692: 00362 | B3692: ITAU UNIBANCO S.A. | C3692: 60158-CARTAO DE CREDITO | D3692: 12/2025 | E3692: 46021 | F3692: 46021 | G3692: 13710.13 | H3692: 0 | I3692: 0 | J3692: 0 | K3692: 1800 | L3692: Banco Investimentos | M3692: =YEAR(F3692) -> 2025
A3693: 154 | B3693: Uber/ frete | C3693: 60083-TRANSPORTES E FRETES | D3693: 46023 | E3693: 46030 | F3693: 46030 | G3693: 47 | H3693: 0 | I3693: 0 | J3693: 0 | K3693: 47 | L3693: Dinheiro | M3693: =YEAR(F3693) -> 2026
A3694: 111 | B3694: Thayna Cristine | C3694: 60030-PREMIACOES E GRATIFICACOES | D3694: 46023 | E3694: 46031 | F3694: 46031 | G3694: 550 | H3694: 0 | I3694: 0 | J3694: 0 | K3694: 550 | L3694: Dinheiro | M3694: =YEAR(F3694) -> 2026
A3695: 331 | B3695: Ricardo Da Silva Lino | C3695: 60030-PREMIACOES E GRATIFICACOES | D3695: 46023 | E3695: 46031 | F3695: 46031 | G3695: 275 | H3695: 0 | I3695: 0 | J3695: 0 | K3695: 275 | L3695: Dinheiro | M3695: =YEAR(F3695) -> 2026
A3696: 398 | B3696: Ana Cristina Pereira | C3696: 60004-INSTRUTOR | D3696: 46023 | E3696: 46032 | F3696: 46035 | G3696: 320 | H3696: 0 | I3696: 0 | J3696: 0 | K3696: 320 | L3696: Dinheiro | M3696: =YEAR(F3696) -> 2026
A3697: 409 | B3697: Ryan Miguel Novaes dos Santos | C3697: 60023-VALE TRANSPORTE | D3697: 46023 | E3697: 46042 | F3697: 46042 | G3697: 240 | H3697: 0 | I3697: 0 | J3697: 0 | K3697: 240 | L3697: Dinheiro | M3697: =YEAR(F3697) -> 2026
A3698: 00039 | B3698: Barkev Materiais de Construções LTDA | C3698: 60047-MANUTENCAO PREDIAL | D3698: 01/2026 | E3698: 46024 | F3698: 46024 | G3698: 42 | H3698: 0 | I3698: 0 | J3698: 0 | K3698: 42 | L3698: Dinheiro | M3698: =YEAR(F3698) -> 2026
A3699: 00663 | B3699: MARIA PAULA DA SILVA SOUSA | C3699: 60023-VALE TRANSPORTE | D3699: 01/2026 | E3699: 46024 | F3699: 46024 | G3699: 11 | H3699: 0 | I3699: 0 | J3699: 0 | K3699: 11 | L3699: Dinheiro | M3699: =YEAR(F3699) -> 2026
A3700: 00039 | B3700: Barkev Materiais de Construções LTDA | C3700: 60047-MANUTENCAO PREDIAL | D3700: 01/2026 | E3700: 46027 | F3700: 46027 | G3700: 48.7 | H3700: 0 | I3700: 0 | J3700: 0 | K3700: 48.7 | L3700: Dinheiro | M3700: =YEAR(F3700) -> 2026
A3701: 00613 | B3701: JULIANA MARIA VICENTE BOTELHO | C3701: 60030-PREMIACOES E GRATIFICACOES | D3701: 01/2026 | E3701: 46027 | F3701: 46027 | G3701: 40 | H3701: 0 | I3701: 0 | J3701: 0 | K3701: 40 | L3701: Dinheiro | M3701: =YEAR(F3701) -> 2026
A3702: 00364 | B3702: Naiara Oliveira Rodrigues | C3702: 60030-PREMIACOES E GRATIFICACOES | D3702: 01/2026 | E3702: 46027 | F3702: 46027 | G3702: 66 | H3702: 0 | I3702: 0 | J3702: 0 | K3702: 66 | L3702: Dinheiro | M3702: =YEAR(F3702) -> 2026
A3703: 00467 | B3703: Chavelândia | C3703: 60077-IMPRESSOES / COPIAS / CARIMBOS / CARTOES | D3703: 01/2026 | E3703: 46028 | F3703: 46028 | G3703: 12 | H3703: 0 | I3703: 0 | J3703: 0 | K3703: 12 | L3703: Dinheiro | M3703: =YEAR(F3703) -> 2026
A3704: 00036 | B3704: Casulo Destribuidora de Doces LDTA | C3704: 60063-FESTAS E CONFRATERNIZACOES | D3704: 01/2026 | E3704: 46028 | F3704: 46028 | G3704: 13.99 | H3704: 0 | I3704: 0 | J3704: 0 | K3704: 13.99 | L3704: Dinheiro | M3704: =YEAR(F3704) -> 2026
...

Sheet REAL_X_ORC_MAIO
A1: COMPARATIVO REAL x ORÇADO - MAIO/2026 | H1: 🔄 Dados vinculados à DIN_TAXA - ATUALIZAÇÃO AUTOMÁTICA
A2: TOTAL | C2: =SUM(C4:C107) -> 325529.15 | D2: =SUM(D4:D107) -> 333682.87 | E2: =D2-C2 -> 8153.7233 | F2: =IF(C2=0,0,(D2-C2)/C2) -> 0.025047598 | H2: 46168
A3: Despesa | C3: Orçado (Mai) | D3: Real (Mai) | E3: Diferença | F3: Var % | H3: 📊 RESUMO
A4: 60004-INSTRUTOR | C4: =IFERROR(VLOOKUP(A4,PROJECAO_2026!$A$4:$F$120,6,FALSE),0) -> 35000 | D4: =IFERROR(VLOOKUP(A4,DIN_TAXA!$A$14:$G$121,7,FALSE),0) -> 33515 | E4: =D4-C4 -> -1485 | F4: =IF(C4=0,IF(D4=0,"0%","N/A"),TEXT((D4-C4)/C4,"0%")) -> -4% | H4: Orçado Maio: | I4: =C2 -> 325529.15
A5: 60013-SALARIOS | C5: =IFERROR(VLOOKUP(A5,PROJECAO_2026!$A$4:$F$120,6,FALSE),0) -> 33243.065 | D5: =IFERROR(VLOOKUP(A5,DIN_TAXA!$A$14:$G$121,7,FALSE),0) -> 34895.88 | E5: =D5-C5 -> 1652.815 | F5: =IF(C5=0,IF(D5=0,"0%","N/A"),TEXT((D5-C5)/C5,"0%")) -> 5% | H5: Real Maio: | I5: =D2 -> 333682.87
A6: 60040-ALUGUEL | C6: =IFERROR(VLOOKUP(A6,PROJECAO_2026!$A$4:$F$120,6,FALSE),0) -> 28087.8 | D6: =IFERROR(VLOOKUP(A6,DIN_TAXA!$A$14:$G$121,7,FALSE),0) -> 28087.8 | E6: =D6-C6 -> 0 | F6: =IF(C6=0,IF(D6=0,"0%","N/A"),TEXT((D6-C6)/C6,"0%")) -> 0% | H6: % Executado: | I6: =IF(C2=0,0,D2/C2) -> 1.0250476
A7: 60106-JUROS E TAXAS SOBRE EMPRESTIMOS | C7: =IFERROR(VLOOKUP(A7,PROJECAO_2026!$A$4:$F$120,6,FALSE),0) -> 20541.693 | D7: =IFERROR(VLOOKUP(A7,DIN_TAXA!$A$14:$G$121,7,FALSE),0) -> 20788.27 | E7: =D7-C7 -> 246.57667 | F7: =IF(C7=0,IF(D7=0,"0%","N/A"),TEXT((D7-C7)/C7,"0%")) -> 1% | H7: Saldo a Pagar: | I7: =C2-D2 -> -8153.7233
A8: 60119-SIMPLES NACIONAL | C8: =IFERROR(VLOOKUP(A8,PROJECAO_2026!$A$4:$F$120,6,FALSE),0) -> 19678.093 | D8: =IFERROR(VLOOKUP(A8,DIN_TAXA!$A$14:$G$121,7,FALSE),0) -> 18702.19 | E8: =D8-C8 -> -975.90333 | F8: =IF(C8=0,IF(D8=0,"0%","N/A"),TEXT((D8-C8)/C8,"0%")) -> -5%
A9: 60052-ROYALTIES | C9: =IFERROR(VLOOKUP(A9,PROJECAO_2026!$A$4:$F$120,6,FALSE),0) -> 22000 | D9: =IFERROR(VLOOKUP(A9,DIN_TAXA!$A$14:$G$121,7,FALSE),0) -> 24737.21 | E9: =D9-C9 -> 2737.21 | F9: =IF(C9=0,IF(D9=0,"0%","N/A"),TEXT((D9-C9)/C9,"0%")) -> 12% | H9: 🔴 CONTAS MAIS ESTOURADAS (Diferença ≥ R$ 1.000)
A10: 60030-PREMIACOES E GRATIFICACOES | C10: =IFERROR(VLOOKUP(A10,PROJECAO_2026!$A$4:$F$120,6,FALSE),0) -> 12000 | D10: =IFERROR(VLOOKUP(A10,DIN_TAXA!$A$14:$G$121,7,FALSE),0) -> 11303.6 | E10: =D10-C10 -> -696.4 | F10: =IF(C10=0,IF(D10=0,"0%","N/A"),TEXT((D10-C10)/C10,"0%")) -> -6% | H10: Despesa | I10: Orçado | J10: Real | K10: Diferença | L10: Var %
A11: 60005-PRECEPTOR | C11: =IFERROR(VLOOKUP(A11,PROJECAO_2026!$A$4:$F$120,6,FALSE),0) -> 16000 | D11: =IFERROR(VLOOKUP(A11,DIN_TAXA!$A$14:$G$121,7,FALSE),0) -> 17580 | E11: =D11-C11 -> 1580 | F11: =IF(C11=0,IF(D11=0,"0%","N/A"),TEXT((D11-C11)/C11,"0%")) -> 10% | H11: {=IFERROR(INDEX($A$4:$A$107,MATCH(LARGE(IF($E$4:$E$107>=1000,$E$4:$E$107),1),$E$4:$E$107,0)),"")} -> 60147-CREDENCIAMENTO NOVOS CURSOS | I11: =IFERROR(VLOOKUP(H11,$A$4:$C$107,3,FALSE),0) -> 0 | J11: =IFERROR(VLOOKUP(H11,$A$4:$D$107,4,FALSE),0) -> 3995.68 | K11: =IFERROR(VLOOKUP(H11,$A$4:$E$107,5,FALSE),0) -> 3995.68 | L11: =IFERROR(VLOOKUP(H11,$A$4:$F$107,6,FALSE),"-") -> N/A
A12: 60158-CARTAO DE CREDITO | C12: =IFERROR(VLOOKUP(A12,PROJECAO_2026!$A$4:$F$120,6,FALSE),0) -> 10500 | D12: =IFERROR(VLOOKUP(A12,DIN_TAXA!$A$14:$G$121,7,FALSE),0) -> 8683.25 | E12: =D12-C12 -> -1816.75 | F12: =IF(C12=0,IF(D12=0,"0%","N/A"),TEXT((D12-C12)/C12,"0%")) -> -17% | H12: {=IFERROR(INDEX($A$4:$A$107,MATCH(LARGE(IF($E$4:$E$107>=1000,$E$4:$E$107),2),$E$4:$E$107,0)),"")} -> 60003-FARDAMENTO ALUNOS | I12: =IFERROR(VLOOKUP(H12,$A$4:$C$107,3,FALSE),0) -> 2522.5267 | J12: =IFERROR(VLOOKUP(H12,$A$4:$D$107,4,FALSE),0) -> 5808.67 | K12: =IFERROR(VLOOKUP(H12,$A$4:$E$107,5,FALSE),0) -> 3286.1433 | L12: =IFERROR(VLOOKUP(H12,$A$4:$F$107,6,FALSE),"-") -> 130%
A13: 60012-PRO LABORE | C13: =IFERROR(VLOOKUP(A13,PROJECAO_2026!$A$4:$F$120,6,FALSE),0) -> 12000 | D13: =IFERROR(VLOOKUP(A13,DIN_TAXA!$A$14:$G$121,7,FALSE),0) -> 12000 | E13: =D13-C13 -> 0 | F13: =IF(C13=0,IF(D13=0,"0%","N/A"),TEXT((D13-C13)/C13,"0%")) -> 0% | H13: {=IFERROR(INDEX($A$4:$A$107,MATCH(LARGE(IF($E$4:$E$107>=1000,$E$4:$E$107),3),$E$4:$E$107,0)),"")} -> 60052-ROYALTIES | I13: =IFERROR(VLOOKUP(H13,$A$4:$C$107,3,FALSE),0) -> 22000 | J13: =IFERROR(VLOOKUP(H13,$A$4:$D$107,4,FALSE),0) -> 24737.21 | K13: =IFERROR(VLOOKUP(H13,$A$4:$E$107,5,FALSE),0) -> 2737.21 | L13: =IFERROR(VLOOKUP(H13,$A$4:$F$107,6,FALSE),"-") -> 12%
A14: 60109-MIDIA DE INTERNET | C14: =IFERROR(VLOOKUP(A14,PROJECAO_2026!$A$4:$F$120,6,FALSE),0) -> 11984.277 | D14: =IFERROR(VLOOKUP(A14,DIN_TAXA!$A$14:$G$121,7,FALSE),0) -> 7546.7 | E14: =D14-C14 -> -4437.5767 | F14: =IF(C14=0,IF(D14=0,"0%","N/A"),TEXT((D14-C14)/C14,"0%")) -> -37% | H14: {=IFERROR(INDEX($A$4:$A$107,MATCH(LARGE(IF($E$4:$E$107>=1000,$E$4:$E$107),4),$E$4:$E$107,0)),"")} -> 60069-JURIDICO | I14: =IFERROR(VLOOKUP(H14,$A$4:$C$107,3,FALSE),0) -> 1621 | J14: =IFERROR(VLOOKUP(H14,$A$4:$D$107,4,FALSE),0) -> 3601.34 | K14: =IFERROR(VLOOKUP(H14,$A$4:$E$107,5,FALSE),0) -> 1980.34 | L14: =IFERROR(VLOOKUP(H14,$A$4:$F$107,6,FALSE),"-") -> 122%
A15: 60053-FUNDO DE PROPAGANDA | C15: =IFERROR(VLOOKUP(A15,PROJECAO_2026!$A$4:$F$120,6,FALSE),0) -> 11921.15 | D15: =IFERROR(VLOOKUP(A15,DIN_TAXA!$A$14:$G$121,7,FALSE),0) -> 13742.91 | E15: =D15-C15 -> 1821.76 | F15: =IF(C15=0,IF(D15=0,"0%","N/A"),TEXT((D15-C15)/C15,"0%")) -> 15% | H15: {=IFERROR(INDEX($A$4:$A$107,MATCH(LARGE(IF($E$4:$E$107>=1000,$E$4:$E$107),5),$E$4:$E$107,0)),"")} -> 60053-FUNDO DE PROPAGANDA | I15: =IFERROR(VLOOKUP(H15,$A$4:$C$107,3,FALSE),0) -> 11921.15 | J15: =IFERROR(VLOOKUP(H15,$A$4:$D$107,4,FALSE),0) -> 13742.91 | K15: =IFERROR(VLOOKUP(H15,$A$4:$E$107,5,FALSE),0) -> 1821.76 | L15: =IFERROR(VLOOKUP(H15,$A$4:$F$107,6,FALSE),"-") -> 15%
A16: 60001-APOSTILA | C16: =IFERROR(VLOOKUP(A16,PROJECAO_2026!$A$4:$F$120,6,FALSE),0) -> 10344.513 | D16: =IFERROR(VLOOKUP(A16,DIN_TAXA!$A$14:$G$121,7,FALSE),0) -> 9342.8 | E16: =D16-C16 -> -1001.7133 | F16: =IF(C16=0,IF(D16=0,"0%","N/A"),TEXT((D16-C16)/C16,"0%")) -> -10% | H16: {=IFERROR(INDEX($A$4:$A$107,MATCH(LARGE(IF($E$4:$E$107>=1000,$E$4:$E$107),6),$E$4:$E$107,0)),"")} -> 60013-SALARIOS | I16: =IFERROR(VLOOKUP(H16,$A$4:$C$107,3,FALSE),0) -> 33243.065 | J16: =IFERROR(VLOOKUP(H16,$A$4:$D$107,4,FALSE),0) -> 34895.88 | K16: =IFERROR(VLOOKUP(H16,$A$4:$E$107,5,FALSE),0) -> 1652.815 | L16: =IFERROR(VLOOKUP(H16,$A$4:$F$107,6,FALSE),"-") -> 5%
A17: 60023-VALE TRANSPORTE | C17: =IFERROR(VLOOKUP(A17,PROJECAO_2026!$A$4:$F$120,6,FALSE),0) -> 9618.0533 | D17: =IFERROR(VLOOKUP(A17,DIN_TAXA!$A$14:$G$121,7,FALSE),0) -> 9140.26 | E17: =D17-C17 -> -477.79333 | F17: =IF(C17=0,IF(D17=0,"0%","N/A"),TEXT((D17-C17)/C17,"0%")) -> -5% | H17: {=IFERROR(INDEX($A$4:$A$107,MATCH(LARGE(IF($E$4:$E$107>=1000,$E$4:$E$107),7),$E$4:$E$107,0)),"")} -> 60005-PRECEPTOR | I17: =IFERROR(VLOOKUP(H17,$A$4:$C$107,3,FALSE),0) -> 16000 | J17: =IFERROR(VLOOKUP(H17,$A$4:$D$107,4,FALSE),0) -> 17580 | K17: =IFERROR(VLOOKUP(H17,$A$4:$E$107,5,FALSE),0) -> 1580 | L17: =IFERROR(VLOOKUP(H17,$A$4:$F$107,6,FALSE),"-") -> 10%
A18: 60009-SERVICOS DE ASSESSORIA PEDAGOGICA | C18: =IFERROR(VLOOKUP(A18,PROJECAO_2026!$A$4:$F$120,6,FALSE),0) -> 8076 | D18: =IFERROR(VLOOKUP(A18,DIN_TAXA!$A$14:$G$121,7,FALSE),0) -> 8798 | E18: =D18-C18 -> 722 | F18: =IF(C18=0,IF(D18=0,"0%","N/A"),TEXT((D18-C18)/C18,"0%")) -> 9% | H18: {=IFERROR(INDEX($A$4:$A$107,MATCH(LARGE(IF($E$4:$E$107>=1000,$E$4:$E$107),8),$E$4:$E$107,0)),"")} -> 60082-ASSESSORIA OU CONSULTORIA OPERACIONAL | I18: =IFERROR(VLOOKUP(H18,$A$4:$C$107,3,FALSE),0) -> 0 | J18: =IFERROR(VLOOKUP(H18,$A$4:$D$107,4,FALSE),0) -> 1500 | K18: =IFERROR(VLOOKUP(H18,$A$4:$E$107,5,FALSE),0) -> 1500 | L18: =IFERROR(VLOOKUP(H18,$A$4:$F$107,6,FALSE),"-") -> N/A
A19: 60159-CONTRA PARTIDA DE ESTAGIO | C19: =IFERROR(VLOOKUP(A19,PROJECAO_2026!$A$4:$F$120,6,FALSE),0) -> 3500 | D19: =IFERROR(VLOOKUP(A19,DIN_TAXA!$A$14:$G$121,7,FALSE),0) -> 4055 | E19: =D19-C19 -> 555 | F19: =IF(C19=0,IF(D19=0,"0%","N/A"),TEXT((D19-C19)/C19,"0%")) -> 16% | H19: {=IFERROR(INDEX($A$4:$A$107,MATCH(LARGE(IF($E$4:$E$107>=1000,$E$4:$E$107),9),$E$4:$E$107,0)),"")} -> 70017-MATERIAIS AÇÃO DE SAÚDE/EVENTOS | I19: =IFERROR(VLOOKUP(H19,$A$4:$C$107,3,FALSE),0) -> 76.056667 | J19: =IFERROR(VLOOKUP(H19,$A$4:$D$107,4,FALSE),0) -> 1087.9 | K19: =IFERROR(VLOOKUP(H19,$A$4:$E$107,5,FALSE),0) -> 1011.8433 | L19: =IFERROR(VLOOKUP(H19,$A$4:$F$107,6,FALSE),"-") -> 1330%
A20: 60022-VALE ALIMENTACAO / REFEICAO | C20: =IFERROR(VLOOKUP(A20,PROJECAO_2026!$A$4:$F$120,6,FALSE),0) -> 5311.5633 | D20: =IFERROR(VLOOKUP(A20,DIN_TAXA!$A$14:$G$121,7,FALSE),0) -> 5858.22 | E20: =D20-C20 -> 546.65667 | F20: =IF(C20=0,IF(D20=0,"0%","N/A"),TEXT((D20-C20)/C20,"0%")) -> 10% | H20: TOTAL ESTOUROS | I20: =SUM(I11:I19) -> 87383.798 | J20: =SUM(J11:J19) -> 106949.59 | K20: =SUM(K11:K19) -> 19565.792 | L20: -
A21: 60018-FGTS SALARIO | C21: =IFERROR(VLOOKUP(A21,PROJECAO_2026!$A$4:$F$120,6,FALSE),0) -> 5026.92 | D21: =IFERROR(VLOOKUP(A21,DIN_TAXA!$A$14:$G$121,7,FALSE),0) -> 1473.02 | E21: =D21-C21 -> -3553.9 | F21: =IF(C21=0,IF(D21=0,"0%","N/A"),TEXT((D21-C21)/C21,"0%")) -> -71% | H21: 🟢 CONTAS COM MAIOR ECONOMIA (Diferença ≤ -R$ 1.000)
A22: 60047-MANUTENCAO PREDIAL | C22: =IFERROR(VLOOKUP(A22,PROJECAO_2026!$A$4:$F$120,6,FALSE),0) -> 3809.485 | D22: =IFERROR(VLOOKUP(A22,DIN_TAXA!$A$14:$G$121,7,FALSE),0) -> 4076.43 | E22: =D22-C22 -> 266.945 | F22: =IF(C22=0,IF(D22=0,"0%","N/A"),TEXT((D22-C22)/C22,"0%")) -> 7% | H22: Despesa | I22: Orçado | J22: Real | K22: Economia | L22: Var %
A23: 60042-ENERGIA ELETRICA | C23: =IFERROR(VLOOKUP(A23,PROJECAO_2026!$A$4:$F$120,6,FALSE),0) -> 4578.6933 | D23: =IFERROR(VLOOKUP(A23,DIN_TAXA!$A$14:$G$121,7,FALSE),0) -> 5096.29 | E23: =D23-C23 -> 517.59667 | F23: =IF(C23=0,IF(D23=0,"0%","N/A"),TEXT((D23-C23)/C23,"0%")) -> 11% | H23: {=IFERROR(INDEX($A$4:$A$107,MATCH(SMALL(IF($E$4:$E$107<=-1000,$E$4:$E$107),1),$E$4:$E$107,0)),"")} -> 60109-MIDIA DE INTERNET | I23: =IFERROR(VLOOKUP(H23,$A$4:$C$107,3,FALSE),0) -> 11984.277 | J23: =IFERROR(VLOOKUP(H23,$A$4:$D$107,4,FALSE),0) -> 7546.7 | K23: =IFERROR(VLOOKUP(H23,$A$4:$E$107,5,FALSE),0) -> -4437.5767 | L23: =IFERROR(VLOOKUP(H23,$A$4:$F$107,6,FALSE),"-") -> -37%
A24: 60098-TARIFAS BANCARIAS | C24: =IFERROR(VLOOKUP(A24,PROJECAO_2026!$A$4:$F$120,6,FALSE),0) -> 4439.0967 | D24: =IFERROR(VLOOKUP(A24,DIN_TAXA!$A$14:$G$121,7,FALSE),0) -> 4691.76 | E24: =D24-C24 -> 252.66333 | F24: =IF(C24=0,IF(D24=0,"0%","N/A"),TEXT((D24-C24)/C24,"0%")) -> 6% | H24: {=IFERROR(INDEX($A$4:$A$107,MATCH(SMALL(IF($E$4:$E$107<=-1000,$E$4:$E$107),2),$E$4:$E$107,0)),"")} -> 60018-FGTS SALARIO | I24: =IFERROR(VLOOKUP(H24,$A$4:$C$107,3,FALSE),0) -> 5026.92 | J24: =IFERROR(VLOOKUP(H24,$A$4:$D$107,4,FALSE),0) -> 1473.02 | K24: =IFERROR(VLOOKUP(H24,$A$4:$E$107,5,FALSE),0) -> -3553.9 | L24: =IFERROR(VLOOKUP(H24,$A$4:$F$107,6,FALSE),"-") -> -71%
A25: 60080-ALUGUEL / ASSINATURA DE SISTEMAS | C25: =IFERROR(VLOOKUP(A25,PROJECAO_2026!$A$4:$F$120,6,FALSE),0) -> 4058.85 | D25: =IFERROR(VLOOKUP(A25,DIN_TAXA!$A$14:$G$121,7,FALSE),0) -> 4014.36 | E25: =D25-C25 -> -44.49 | F25: =IF(C25=0,IF(D25=0,"0%","N/A"),TEXT((D25-C25)/C25,"0%")) -> -1% | H25: {=IFERROR(INDEX($A$4:$A$107,MATCH(SMALL(IF($E$4:$E$107<=-1000,$E$4:$E$107),3),$E$4:$E$107,0)),"")} -> 60158-CARTAO DE CREDITO | I25: =IFERROR(VLOOKUP(H25,$A$4:$C$107,3,FALSE),0) -> 10500 | J25: =IFERROR(VLOOKUP(H25,$A$4:$D$107,4,FALSE),0) -> 8683.25 | K25: =IFERROR(VLOOKUP(H25,$A$4:$E$107,5,FALSE),0) -> -1816.75 | L25: =IFERROR(VLOOKUP(H25,$A$4:$F$107,6,FALSE),"-") -> -17%
A26: 60084-OUTRAS CONSULTORIAS | C26: =IFERROR(VLOOKUP(A26,PROJECAO_2026!$A$4:$F$120,6,FALSE),0) -> 3168.4067 | D26: =IFERROR(VLOOKUP(A26,DIN_TAXA!$A$14:$G$121,7,FALSE),0) -> 3770 | E26: =D26-C26 -> 601.59333 | F26: =IF(C26=0,IF(D26=0,"0%","N/A"),TEXT((D26-C26)/C26,"0%")) -> 19% | H26: {=IFERROR(INDEX($A$4:$A$107,MATCH(SMALL(IF($E$4:$E$107<=-1000,$E$4:$E$107),4),$E$4:$E$107,0)),"")} -> 60004-INSTRUTOR | I26: =IFERROR(VLOOKUP(H26,$A$4:$C$107,3,FALSE),0) -> 35000 | J26: =IFERROR(VLOOKUP(H26,$A$4:$D$107,4,FALSE),0) -> 33515 | K26: =IFERROR(VLOOKUP(H26,$A$4:$E$107,5,FALSE),0) -> -1485 | L26: =IFERROR(VLOOKUP(H26,$A$4:$F$107,6,FALSE),"-") -> -4%
A27: 60017-INSS SALARIO | C27: =IFERROR(VLOOKUP(A27,PROJECAO_2026!$A$4:$F$120,6,FALSE),0) -> 2577.71 | D27: =IFERROR(VLOOKUP(A27,DIN_TAXA!$A$14:$G$121,7,FALSE),0) -> 3101.82 | E27: =D27-C27 -> 524.11 | F27: =IF(C27=0,IF(D27=0,"0%","N/A"),TEXT((D27-C27)/C27,"0%")) -> 20% | H27: {=IFERROR(INDEX($A$4:$A$107,MATCH(SMALL(IF($E$4:$E$107<=-1000,$E$4:$E$107),5),$E$4:$E$107,0)),"")} -> 60001-APOSTILA | I27: =IFERROR(VLOOKUP(H27,$A$4:$C$107,3,FALSE),0) -> 10344.513 | J27: =IFERROR(VLOOKUP(H27,$A$4:$D$107,4,FALSE),0) -> 9342.8 | K27: =IFERROR(VLOOKUP(H27,$A$4:$E$107,5,FALSE),0) -> -1001.7133 | L27: =IFERROR(VLOOKUP(H27,$A$4:$F$107,6,FALSE),"-") -> -10%
A28: 60003-FARDAMENTO ALUNOS | C28: =IFERROR(VLOOKUP(A28,PROJECAO_2026!$A$4:$F$120,6,FALSE),0) -> 2522.5267 | D28: =IFERROR(VLOOKUP(A28,DIN_TAXA!$A$14:$G$121,7,FALSE),0) -> 5808.67 | E28: =D28-C28 -> 3286.1433 | F28: =IF(C28=0,IF(D28=0,"0%","N/A"),TEXT((D28-C28)/C28,"0%")) -> 130% | H28: TOTAL ECONOMIAS | I28: =SUM(I23:I27) -> 72855.71 | J28: =SUM(J23:J27) -> 60560.77 | K28: =SUM(K23:K27) -> -12294.94 | L28: -
A29: 60019-RESCISOES / IDENIZACOES | C29: =IFERROR(VLOOKUP(A29,PROJECAO_2026!$A$4:$F$120,6,FALSE),0) -> 1600 | D29: =IFERROR(VLOOKUP(A29,DIN_TAXA!$A$14:$G$121,7,FALSE),0) -> 2002.16 | E29: =D29-C29 -> 402.16 | F29: =IF(C29=0,IF(D29=0,"0%","N/A"),TEXT((D29-C29)/C29,"0%")) -> 25%
A30: 60014-FERIAS | C30: =IFERROR(VLOOKUP(A30,PROJECAO_2026!$A$4:$F$120,6,FALSE),0) -> 2000 | D30: =IFERROR(VLOOKUP(A30,DIN_TAXA!$A$14:$G$121,7,FALSE),0) -> 2245.5 | E30: =D30-C30 -> 245.5 | F30: =IF(C30=0,IF(D30=0,"0%","N/A"),TEXT((D30-C30)/C30,"0%")) -> 12% | H30: 📌 Os quadros acima são atualizados automaticamente quando os dados da DIN_TAXA são alterados
A31: 60068-CONTABILIDADE | C31: =IFERROR(VLOOKUP(A31,PROJECAO_2026!$A$4:$F$120,6,FALSE),0) -> 1646 | D31: =IFERROR(VLOOKUP(A31,DIN_TAXA!$A$14:$G$121,7,FALSE),0) -> 1621 | E31: =D31-C31 -> -25 | F31: =IF(C31=0,IF(D31=0,"0%","N/A"),TEXT((D31-C31)/C31,"0%")) -> -2%
A32: 60027-AJUDA DE CUSTOS PESSOAL | C32: =IFERROR(VLOOKUP(A32,PROJECAO_2026!$A$4:$F$120,6,FALSE),0) -> 1942.4733 | D32: =IFERROR(VLOOKUP(A32,DIN_TAXA!$A$14:$G$121,7,FALSE),0) -> 1980 | E32: =D32-C32 -> 37.526667 | F32: =IF(C32=0,IF(D32=0,"0%","N/A"),TEXT((D32-C32)/C32,"0%")) -> 2%
A33: 60043-AGUA E ESGOTO | C33: =IFERROR(VLOOKUP(A33,PROJECAO_2026!$A$4:$F$120,6,FALSE),0) -> 1911.2533 | D33: =IFERROR(VLOOKUP(A33,DIN_TAXA!$A$14:$G$121,7,FALSE),0) -> 2516.22 | E33: =D33-C33 -> 604.96667 | F33: =IF(C33=0,IF(D33=0,"0%","N/A"),TEXT((D33-C33)/C33,"0%")) -> 32%
A34: 60008-EQUIPAMENTOS LOCADOS PARA ENSINO | C34: =IFERROR(VLOOKUP(A34,PROJECAO_2026!$A$4:$F$120,6,FALSE),0) -> 1861.3667 | D34: =IFERROR(VLOOKUP(A34,DIN_TAXA!$A$14:$G$121,7,FALSE),0) -> 1439.58 | E34: =D34-C34 -> -421.78667 | F34: =IF(C34=0,IF(D34=0,"0%","N/A"),TEXT((D34-C34)/C34,"0%")) -> -23%
A35: 60069-JURIDICO | C35: =IFERROR(VLOOKUP(A35,PROJECAO_2026!$A$4:$F$120,6,FALSE),0) -> 1621 | D35: =IFERROR(VLOOKUP(A35,DIN_TAXA!$A$14:$G$121,7,FALSE),0) -> 3601.34 | E35: =D35-C35 -> 1980.34 | F35: =IF(C35=0,IF(D35=0,"0%","N/A"),TEXT((D35-C35)/C35,"0%")) -> 122%
A36: 60020-FGTS RESCISORIO | C36: =IFERROR(VLOOKUP(A36,PROJECAO_2026!$A$4:$F$120,6,FALSE),0) -> 1100 | D36: =IFERROR(VLOOKUP(A36,DIN_TAXA!$A$14:$G$121,7,FALSE),0) -> 165.15 | E36: =D36-C36 -> -934.85 | F36: =IF(C36=0,IF(D36=0,"0%","N/A"),TEXT((D36-C36)/C36,"0%")) -> -85%
A37: 60083-TRANSPORTES E FRETES | C37: =IFERROR(VLOOKUP(A37,PROJECAO_2026!$A$4:$F$120,6,FALSE),0) -> 1212.6133 | D37: =IFERROR(VLOOKUP(A37,DIN_TAXA!$A$14:$G$121,7,FALSE),0) -> 1338.72 | E37: =D37-C37 -> 126.10667 | F37: =IF(C37=0,IF(D37=0,"0%","N/A"),TEXT((D37-C37)/C37,"0%")) -> 10%
A38: 60057-MATERIAL DE LIMPEZA E CONSERVACAO | C38: =IFERROR(VLOOKUP(A38,PROJECAO_2026!$A$4:$F$120,6,FALSE),0) -> 1206.0333 | D38: =IFERROR(VLOOKUP(A38,DIN_TAXA!$A$14:$G$121,7,FALSE),0) -> 2094.25 | E38: =D38-C38 -> 888.21667 | F38: =IF(C38=0,IF(D38=0,"0%","N/A"),TEXT((D38-C38)/C38,"0%")) -> 74%
A39: 60039-BOLSA ESTAGIARIOS | C39: =IFERROR(VLOOKUP(A39,PROJECAO_2026!$A$4:$F$120,6,FALSE),0) -> 974.28667 | D39: =IFERROR(VLOOKUP(A39,DIN_TAXA!$A$14:$G$121,7,FALSE),0) -> 129.97 | E39: =D39-C39 -> -844.31667 | F39: =IF(C39=0,IF(D39=0,"0%","N/A"),TEXT((D39-C39)/C39,"0%")) -> -87%
A40: 60081-SERVICO TECNOLOGIA DA INFORMACAO | C40: =IFERROR(VLOOKUP(A40,PROJECAO_2026!$A$4:$F$120,6,FALSE),0) -> 900 | D40: =IFERROR(VLOOKUP(A40,DIN_TAXA!$A$14:$G$121,7,FALSE),0) -> 900 | E40: =D40-C40 -> 0 | F40: =IF(C40=0,IF(D40=0,"0%","N/A"),TEXT((D40-C40)/C40,"0%")) -> 0%
...

Sheet PROJECAO_2026
A1: PROJEÇÃO DE DESPESAS 2026
A2: TOTAL MÊS | B2: =SUM(B4:B99) -> 311536.31 | C2: =SUM(C4:C99) -> 327176.73 | D2: =SUM(D4:D99) -> 332002.42 | E2: =SUM(E4:E99) -> 366849.77 | F2: =SUM(F4:F99) -> 325529.15 | G2: =SUM(G4:G99) -> 325529.15 | H2: =SUM(H4:H99) -> 325529.15 | I2: =SUM(I4:I99) -> 325529.15 | ... M2: =SUM(M4:M99) -> 325529.15 | N2: =SUM(B2:M2) -> 3941798.4
A3: Despesa | B3: Jan | C3: Fev | D3: Mar | E3: Abr | F3: Mai | G3: Jun | H3: Jul | I3: Ago | J3: Set | K3: Out | L3: Nov | M3: Dez | N3: Total Ano | O3: Base Projeção
A4: 60013-SALARIOS | B4: 34102 | C4: 34603 | D4: 31312.18 | E4: 32955.08 | F4: =IFERROR(AVERAGE($B$4:$E$4),0) -> 33243.065 | G4: =IFERROR(AVERAGE($B$4:$E$4),0) -> 33243.065 | H4: =IFERROR(AVERAGE($B$4:$E$4),0) -> 33243.065 | I4: =IFERROR(AVERAGE($B$4:$E$4),0) -> 33243.065 | J4: =IFERROR(AVERAGE($B$4:$E$4),0) -> 33243.065 | K4: =IFERROR(AVERAGE($B$4:$E$4),0) -> 33243.065 | L4: =IFERROR(AVERAGE($B$4:$E$4),0) -> 33243.065 | M4: =IFERROR(AVERAGE($B$4:$E$4),0) -> 33243.065 | N4: =SUM(B4:M4) -> 398916.78 | O4: Abril (ref.)
A5: 60004-INSTRUTOR | B5: 22440 | C5: 32472 | D5: 25036 | E5: 37714 | F5: 35000 | G5: =F5 -> 35000 | H5: =G5 -> 35000 | I5: =H5 -> 35000 | J5: =I5 -> 35000 | K5: =J5 -> 35000 | L5: =K5 -> 35000 | M5: =L5 -> 35000 | N5: =SUM(B5:M5) -> 397662 | O5: Maio (ref.)
A6: 60040-ALUGUEL | B6: 27343.18 | C6: 27343.18 | D6: 25123.8 | E6: 28087.8 | F6: =E6 -> 28087.8 | G6: =F6 -> 28087.8 | H6: =G6 -> 28087.8 | I6: =H6 -> 28087.8 | J6: =I6 -> 28087.8 | K6: =J6 -> 28087.8 | L6: =K6 -> 28087.8 | M6: =L6 -> 28087.8 | N6: =SUM(B6:M6) -> 332600.36 | O6: Abril (ref.)
A7: 60119-SIMPLES NACIONAL | B7: 20778.97 | C7: 18546.78 | D7: 19708.53 | E7: 18081.14 | F7: =IFERROR(AVERAGE(B7:D7),0) -> 19678.093 | G7: =IFERROR(AVERAGE(B7:D7),0) -> 19678.093 | H7: =IFERROR(AVERAGE(B7:D7),0) -> 19678.093 | I7: =IFERROR(AVERAGE(B7:D7),0) -> 19678.093 | J7: =IFERROR(AVERAGE(B7:D7),0) -> 19678.093 | K7: =IFERROR(AVERAGE(B7:D7),0) -> 19678.093 | L7: =IFERROR(AVERAGE(B7:D7),0) -> 19678.093 | M7: =IFERROR(AVERAGE(B7:D7),0) -> 19678.093 | N7: =SUM(B7:M7) -> 234540.17 | O7: Média Jan-Mar
A8: 60005-PRECEPTOR | B8: 12880 | C8: 9860 | D8: 13240 | E8: 16020 | F8: 16000 | G8: =F8 -> 16000 | H8: =G8 -> 16000 | I8: =H8 -> 16000 | J8: =I8 -> 16000 | K8: =J8 -> 16000 | L8: =K8 -> 16000 | M8: =L8 -> 16000 | N8: =SUM(B8:M8) -> 180000 | O8: Abril (ref.)
A9: 60052-ROYALTIES | B9: 12717.54 | C9: 24839.94 | D9: 20571.58 | E9: 26432.78 | F9: 22000 | G9: 22000 | H9: 22000 | I9: 22000 | J9: 22000 | K9: 22000 | L9: 22000 | M9: 22000 | N9: =SUM(B9:M9) -> 260561.84 | O9: Maio (ref.)
A10: 60106-JUROS E TAXAS SOBRE EMPRESTIMOS | B10: 19355.85 | C10: 21052.12 | D10: 21217.11 | E10: 21068.72 | F10: =IFERROR(AVERAGE(B10:D10),0) -> 20541.693 | G10: =IFERROR(AVERAGE(B10:D10),0) -> 20541.693 | H10: =IFERROR(AVERAGE(B10:D10),0) -> 20541.693 | I10: =IFERROR(AVERAGE(B10:D10),0) -> 20541.693 | J10: =IFERROR(AVERAGE(B10:D10),0) -> 20541.693 | K10: =IFERROR(AVERAGE(B10:D10),0) -> 20541.693 | L10: =IFERROR(AVERAGE(B10:D10),0) -> 20541.693 | M10: =IFERROR(AVERAGE(B10:D10),0) -> 20541.693 | N10: =SUM(B10:M10) -> 247027.35 | O10: Média Jan-Abr
A11: 60158-CARTAO DE CREDITO | B11: 11777.86 | C11: 13409.63 | D11: 12597.71 | E11: 10213.05 | F11: 10500 | G11: 10500 | H11: 10500 | I11: 10500 | J11: 10500 | K11: 10500 | L11: 10500 | M11: 10500 | N11: =SUM(B11:M11) -> 131998.25 | O11: Maio (ref.)
A12: 60030-PREMIACOES E GRATIFICACOES | B12: 10121 | C12: 21688 | D12: 17749 | E12: 17470 | F12: 12000 | G12: 12000 | H12: 12000 | I12: 12000 | J12: 12000 | K12: 12000 | L12: 12000 | M12: 12000 | N12: =SUM(B12:M12) -> 163028 | O12: Maio (ref.)
A13: 60001-APOSTILA | B13: 15185.37 | C13: 3152.57 | D13: 12695.6 | E13: 21146.35 | F13: =IFERROR(AVERAGE(B13:D13),0) -> 10344.513 | G13: =IFERROR(AVERAGE(B13:D13),0) -> 10344.513 | H13: =IFERROR(AVERAGE(B13:D13),0) -> 10344.513 | I13: =IFERROR(AVERAGE(B13:D13),0) -> 10344.513 | J13: =IFERROR(AVERAGE(B13:D13),0) -> 10344.513 | K13: =IFERROR(AVERAGE(B13:D13),0) -> 10344.513 | L13: =IFERROR(AVERAGE(B13:D13),0) -> 10344.513 | M13: =IFERROR(AVERAGE(B13:D13),0) -> 10344.513 | N13: =SUM(B13:M13) -> 134936 | O13: Média Jan-Mar
A14: 60109-MIDIA DE INTERNET | B14: 11910.26 | C14: 12041.64 | D14: 12000.93 | E14: 11732.48 | F14: =IFERROR(AVERAGE(B14:D14),0) -> 11984.277 | G14: =IFERROR(AVERAGE(B14:D14),0) -> 11984.277 | H14: =IFERROR(AVERAGE(B14:D14),0) -> 11984.277 | I14: =IFERROR(AVERAGE(B14:D14),0) -> 11984.277 | J14: =IFERROR(AVERAGE(B14:D14),0) -> 11984.277 | K14: =IFERROR(AVERAGE(B14:D14),0) -> 11984.277 | L14: =IFERROR(AVERAGE(B14:D14),0) -> 11984.277 | M14: =IFERROR(AVERAGE(B14:D14),0) -> 11984.277 | N14: =SUM(B14:M14) -> 143559.52 | O14: Média Jan-Abr
A15: 60053-FUNDO DE PROPAGANDA | B15: 11568.26 | C15: 11802.77 | D15: 12392.42 | E15: 9304.76 | F15: =IFERROR(AVERAGE(B15:D15),0) -> 11921.15 | G15: =IFERROR(AVERAGE(B15:D15),0) -> 11921.15 | H15: =IFERROR(AVERAGE(B15:D15),0) -> 11921.15 | I15: =IFERROR(AVERAGE(B15:D15),0) -> 11921.15 | J15: =IFERROR(AVERAGE(B15:D15),0) -> 11921.15 | K15: =IFERROR(AVERAGE(B15:D15),0) -> 11921.15 | L15: =IFERROR(AVERAGE(B15:D15),0) -> 11921.15 | M15: =IFERROR(AVERAGE(B15:D15),0) -> 11921.15 | N15: =SUM(B15:M15) -> 140437.41 | O15: Média Jan-Mar
A16: 60023-VALE TRANSPORTE | B16: 10509.42 | C16: 8159.72 | D16: 10185.02 | E16: 9242.4 | F16: =IFERROR(AVERAGE(B16:D16),0) -> 9618.0533 | G16: =IFERROR(AVERAGE(B16:D16),0) -> 9618.0533 | H16: =IFERROR(AVERAGE(B16:D16),0) -> 9618.0533 | I16: =IFERROR(AVERAGE(B16:D16),0) -> 9618.0533 | J16: =IFERROR(AVERAGE(B16:D16),0) -> 9618.0533 | K16: =IFERROR(AVERAGE(B16:D16),0) -> 9618.0533 | L16: =IFERROR(AVERAGE(B16:D16),0) -> 9618.0533 | M16: =IFERROR(AVERAGE(B16:D16),0) -> 9618.0533 | N16: =SUM(B16:M16) -> 115040.99 | O16: Média Jan-Abr
A17: 60009-SERVICOS DE ASSESSORIA PEDAGOGICA | B17: 8260 | C17: 7500 | D17: 8468 | E17: 9037 | F17: =IFERROR(AVERAGE(B17:D17),0) -> 8076 | G17: =IFERROR(AVERAGE(B17:D17),0) -> 8076 | H17: =IFERROR(AVERAGE(B17:D17),0) -> 8076 | I17: =IFERROR(AVERAGE(B17:D17),0) -> 8076 | J17: =IFERROR(AVERAGE(B17:D17),0) -> 8076 | K17: =IFERROR(AVERAGE(B17:D17),0) -> 8076 | L17: =IFERROR(AVERAGE(B17:D17),0) -> 8076 | M17: =IFERROR(AVERAGE(B17:D17),0) -> 8076 | N17: =SUM(B17:M17) -> 97873 | O17: Média Jan-Mar
A18: 60012-PRO LABORE | B18: 12000 | C18: 12000 | D18: 12000 | E18: 12000 | F18: =IFERROR(AVERAGE(B18:D18),0) -> 12000 | G18: =IFERROR(AVERAGE(B18:D18),0) -> 12000 | H18: =IFERROR(AVERAGE(B18:D18),0) -> 12000 | I18: =IFERROR(AVERAGE(B18:D18),0) -> 12000 | J18: =IFERROR(AVERAGE(B18:D18),0) -> 12000 | K18: =IFERROR(AVERAGE(B18:D18),0) -> 12000 | L18: =IFERROR(AVERAGE(B18:D18),0) -> 12000 | M18: =IFERROR(AVERAGE(B18:D18),0) -> 12000 | N18: =SUM(B18:M18) -> 144000 | O18: Valor Fixo
A19: 60022-VALE ALIMENTACAO / REFEICAO | B19: 5462.47 | C19: 5619.24 | D19: 4852.98 | E19: 5652.19 | F19: =IFERROR(AVERAGE(B19:D19),0) -> 5311.5633 | G19: =IFERROR(AVERAGE(B19:D19),0) -> 5311.5633 | H19: =IFERROR(AVERAGE(B19:D19),0) -> 5311.5633 | I19: =IFERROR(AVERAGE(B19:D19),0) -> 5311.5633 | J19: =IFERROR(AVERAGE(B19:D19),0) -> 5311.5633 | K19: =IFERROR(AVERAGE(B19:D19),0) -> 5311.5633 | L19: =IFERROR(AVERAGE(B19:D19),0) -> 5311.5633 | M19: =IFERROR(AVERAGE(B19:D19),0) -> 5311.5633 | N19: =SUM(B19:M19) -> 64079.387 | O19: Média Jan-Mar
A20: 60080-ALUGUEL / ASSINATURA DE SISTEMAS | B20: 3571.66 | C20: 4197.53 | D20: 4407.36 | E20: 3650.66 | F20: =IFERROR(AVERAGE(B20:D20),0) -> 4058.85 | G20: =IFERROR(AVERAGE(B20:D20),0) -> 4058.85 | H20: =IFERROR(AVERAGE(B20:D20),0) -> 4058.85 | I20: =IFERROR(AVERAGE(B20:D20),0) -> 4058.85 | J20: =IFERROR(AVERAGE(B20:D20),0) -> 4058.85 | K20: =IFERROR(AVERAGE(B20:D20),0) -> 4058.85 | L20: =IFERROR(AVERAGE(B20:D20),0) -> 4058.85 | M20: =IFERROR(AVERAGE(B20:D20),0) -> 4058.85 | N20: =SUM(B20:M20) -> 48298.01 | O20: Média Jan-Mar
A21: 60159-CONTRA PARTIDA DE ESTAGIO | B21: 3227.5 | C21: 3527.5 | D21: 9830.59 | E21: 10279.2 | F21: 3500 | G21: 3500 | H21: 3500 | I21: 3500 | J21: 3500 | K21: 3500 | L21: 3500 | M21: 3500 | N21: =SUM(B21:M21) -> 54864.79 | O21: Maio (ref.)
A22: 60067-OUTRAS DESPESAS | B22: 1413.36 | C22: 405.87 | D22: 0 | E22: 524.29 | F22: =IFERROR(AVERAGE(B22:D22),0) -> 606.41 | G22: =IFERROR(AVERAGE(B22:D22),0) -> 606.41 | H22: =IFERROR(AVERAGE(B22:D22),0) -> 606.41 | I22: =IFERROR(AVERAGE(B22:D22),0) -> 606.41 | J22: =IFERROR(AVERAGE(B22:D22),0) -> 606.41 | K22: =IFERROR(AVERAGE(B22:D22),0) -> 606.41 | L22: =IFERROR(AVERAGE(B22:D22),0) -> 606.41 | M22: =IFERROR(AVERAGE(B22:D22),0) -> 606.41 | N22: =SUM(B22:M22) -> 7194.8 | O22: Média Jan-Mar
A23: 60018-FGTS SALARIO | B23: 5776.39 | C23: 4717.62 | D23: 4586.75 | E23: 4640.87 | F23: =IFERROR(AVERAGE(B23:D23),0) -> 5026.92 | G23: =IFERROR(AVERAGE(B23:D23),0) -> 5026.92 | H23: =IFERROR(AVERAGE(B23:D23),0) -> 5026.92 | I23: =IFERROR(AVERAGE(B23:D23),0) -> 5026.92 | J23: =IFERROR(AVERAGE(B23:D23),0) -> 5026.92 | K23: =IFERROR(AVERAGE(B23:D23),0) -> 5026.92 | L23: =IFERROR(AVERAGE(B23:D23),0) -> 5026.92 | M23: =IFERROR(AVERAGE(B23:D23),0) -> 5026.92 | N23: =SUM(B23:M23) -> 59936.99 | O23: Média Jan-Mar
A24: 60069-JURIDICO | B24: 1621 | C24: 9827.92 | D24: 2154.49 | E24: 12509.06 | F24: 1621 | G24: 1621 | H24: 1621 | I24: 1621 | J24: 1621 | K24: 1621 | L24: 1621 | M24: 1621 | N24: =SUM(B24:M24) -> 39080.47 | O24: Média Jan-Mar
A25: 60003-FARDAMENTO ALUNOS | B25: 1996.8 | C25: 1567 | D25: 4003.78 | E25: 4646.21 | F25: =IFERROR(AVERAGE(B25:D25),0) -> 2522.5267 | G25: =IFERROR(AVERAGE(B25:D25),0) -> 2522.5267 | H25: =IFERROR(AVERAGE(B25:D25),0) -> 2522.5267 | I25: =IFERROR(AVERAGE(B25:D25),0) -> 2522.5267 | J25: =IFERROR(AVERAGE(B25:D25),0) -> 2522.5267 | K25: =IFERROR(AVERAGE(B25:D25),0) -> 2522.5267 | L25: =IFERROR(AVERAGE(B25:D25),0) -> 2522.5267 | M25: =IFERROR(AVERAGE(B25:D25),0) -> 2522.5267 | N25: =SUM(B25:M25) -> 32394.003 | O25: Média Jan-Mar
A26: 60047-MANUTENCAO PREDIAL | B26: 6327 | C26: 4782.58 | D26: 3910.29 | E26: 3708.68 | F26: =IFERROR(AVERAGE(D26:E26),0) -> 3809.485 | G26: =F26 -> 3809.485 | H26: =G26 -> 3809.485 | I26: =H26 -> 3809.485 | J26: =I26 -> 3809.485 | K26: =J26 -> 3809.485 | L26: =K26 -> 3809.485 | M26: =L26 -> 3809.485 | N26: =SUM(B26:M26) -> 49204.43 | O26: Média Jan-Mar
A27: 60019-RESCISOES / IDENIZACOES | B27: 1016.14 | C27: 11.26 | D27: 6281.17 | E27: 1600.17 | F27: 1600 | G27: 1600 | H27: 1600 | I27: 1600 | J27: 1600 | K27: 1600 | L27: 1600 | M27: 1600 | N27: =SUM(B27:M27) -> 21708.74 | O27: Abril (ref.)
A28: 60017-INSS SALARIO | B28: 2587.6 | C28: 2614.42 | D28: 2531.11 | E28: 2783.83 | F28: =IFERROR(AVERAGE(B28:D28),0) -> 2577.71 | G28: =IFERROR(AVERAGE(B28:D28),0) -> 2577.71 | H28: =IFERROR(AVERAGE(B28:D28),0) -> 2577.71 | I28: =IFERROR(AVERAGE(B28:D28),0) -> 2577.71 | J28: =IFERROR(AVERAGE(B28:D28),0) -> 2577.71 | K28: =IFERROR(AVERAGE(B28:D28),0) -> 2577.71 | L28: =IFERROR(AVERAGE(B28:D28),0) -> 2577.71 | M28: =IFERROR(AVERAGE(B28:D28),0) -> 2577.71 | N28: =SUM(B28:M28) -> 31138.64 | O28: Média Jan-Mar
A29: 60098-TARIFAS BANCARIAS | B29: 4883.76 | C29: 3885.9 | D29: 4547.63 | E29: 4658.27 | F29: =IFERROR(AVERAGE(B29:D29),0) -> 4439.0967 | G29: =IFERROR(AVERAGE(B29:D29),0) -> 4439.0967 | H29: =IFERROR(AVERAGE(B29:D29),0) -> 4439.0967 | I29: =IFERROR(AVERAGE(B29:D29),0) -> 4439.0967 | J29: =IFERROR(AVERAGE(B29:D29),0) -> 4439.0967 | K29: =IFERROR(AVERAGE(B29:D29),0) -> 4439.0967 | L29: =IFERROR(AVERAGE(B29:D29),0) -> 4439.0967 | M29: =IFERROR(AVERAGE(B29:D29),0) -> 4439.0967 | N29: =SUM(B29:M29) -> 53488.333 | O29: Média Jan-Mar
A30: 60042-ENERGIA ELETRICA | B30: 4397.03 | C30: 4645.44 | D30: 4693.61 | E30: 4100.17 | F30: =IFERROR(AVERAGE(B30:D30),0) -> 4578.6933 | G30: =IFERROR(AVERAGE(B30:D30),0) -> 4578.6933 | H30: =IFERROR(AVERAGE(B30:D30),0) -> 4578.6933 | I30: =IFERROR(AVERAGE(B30:D30),0) -> 4578.6933 | J30: =IFERROR(AVERAGE(B30:D30),0) -> 4578.6933 | K30: =IFERROR(AVERAGE(B30:D30),0) -> 4578.6933 | L30: =IFERROR(AVERAGE(B30:D30),0) -> 4578.6933 | M30: =IFERROR(AVERAGE(B30:D30),0) -> 4578.6933 | N30: =SUM(B30:M30) -> 54465.797 | O30: Média Jan-Mar
A31: 60043-AGUA E ESGOTO | B31: 2250.53 | C31: 1027.31 | D31: 2455.92 | E31: 1757.08 | F31: =IFERROR(AVERAGE(B31:D31),0) -> 1911.2533 | G31: =IFERROR(AVERAGE(B31:D31),0) -> 1911.2533 | H31: =IFERROR(AVERAGE(B31:D31),0) -> 1911.2533 | I31: =IFERROR(AVERAGE(B31:D31),0) -> 1911.2533 | J31: =IFERROR(AVERAGE(B31:D31),0) -> 1911.2533 | K31: =IFERROR(AVERAGE(B31:D31),0) -> 1911.2533 | L31: =IFERROR(AVERAGE(B31:D31),0) -> 1911.2533 | M31: =IFERROR(AVERAGE(B31:D31),0) -> 1911.2533 | N31: =SUM(B31:M31) -> 22780.867 | O31: Média Jan-Mar
A32: 60015-13º SALARIO | B32: 0 | C32: 0 | D32: 0 | E32: 0 | F32: =IFERROR(AVERAGE(B32:D32),0) -> 0 | G32: =IFERROR(AVERAGE(B32:D32),0) -> 0 | H32: =IFERROR(AVERAGE(B32:D32),0) -> 0 | I32: =IFERROR(AVERAGE(B32:D32),0) -> 0 | J32: =IFERROR(AVERAGE(B32:D32),0) -> 0 | K32: =IFERROR(AVERAGE(B32:D32),0) -> 0 | L32: =IFERROR(AVERAGE(B32:D32),0) -> 0 | M32: =IFERROR(AVERAGE(B32:D32),0) -> 0 | N32: =SUM(B32:M32) -> 0 | O32: Sem movimento
A33: 60014-FERIAS | B33: 2243.96 | C33: 1000 | D33: 3318 | E33: 1726.91 | F33: 2000 | G33: 2000 | H33: 2000 | I33: 2000 | J33: 2000 | K33: 2000 | L33: 2000 | M33: 2000 | N33: =SUM(B33:M33) -> 24288.87 | O33: Maio (ref.)
A34: 60068-CONTABILIDADE | B34: 3060.22 | C34: 1621 | D34: 1628.5 | E34: 1646 | F34: 1646 | G34: 1646 | H34: 1646 | I34: 1646 | J34: 1646 | K34: 1646 | L34: 1646 | M34: 1646 | N34: =SUM(B34:M34) -> 21123.72 | O34: Abril (ref.)
A35: 60027-AJUDA DE CUSTOS PESSOAL | B35: 1500 | C35: 2535.42 | D35: 1792 | E35: 1859.64 | F35: =IFERROR(AVERAGE(B35:D35),0) -> 1942.4733 | G35: =IFERROR(AVERAGE(B35:D35),0) -> 1942.4733 | H35: =IFERROR(AVERAGE(B35:D35),0) -> 1942.4733 | I35: =IFERROR(AVERAGE(B35:D35),0) -> 1942.4733 | J35: =IFERROR(AVERAGE(B35:D35),0) -> 1942.4733 | K35: =IFERROR(AVERAGE(B35:D35),0) -> 1942.4733 | L35: =IFERROR(AVERAGE(B35:D35),0) -> 1942.4733 | M35: =IFERROR(AVERAGE(B35:D35),0) -> 1942.4733 | N35: =SUM(B35:M35) -> 23226.847 | O35: Média Jan-Mar
A36: 60057-MATERIAL DE LIMPEZA E CONSERVACAO | B36: 1721.21 | C36: 1708.28 | D36: 188.61 | E36: 1818.99 | F36: =IFERROR(AVERAGE(B36:D36),0) -> 1206.0333 | G36: =IFERROR(AVERAGE(B36:D36),0) -> 1206.0333 | H36: =IFERROR(AVERAGE(B36:D36),0) -> 1206.0333 | I36: =IFERROR(AVERAGE(B36:D36),0) -> 1206.0333 | J36: =IFERROR(AVERAGE(B36:D36),0) -> 1206.0333 | K36: =IFERROR(AVERAGE(B36:D36),0) -> 1206.0333 | L36: =IFERROR(AVERAGE(B36:D36),0) -> 1206.0333 | M36: =IFERROR(AVERAGE(B36:D36),0) -> 1206.0333 | N36: =SUM(B36:M36) -> 15085.357 | O36: Média Jan-Mar
A37: 60020-FGTS RESCISORIO | B37: 2707.76 | C37: 0 | D37: 1125.59 | E37: 864.88 | F37: 1100 | G37: 1100 | H37: 1100 | I37: 1100 | J37: 1100 | K37: 1100 | L37: 1100 | M37: 1100 | N37: =SUM(B37:M37) -> 13498.23 | O37: Maio (ref.)
A38: 60078-LOCACAO DE EQUIPAMENTOS | B38: 390 | C38: 431.59 | D38: 390 | E38: 233.3 | F38: =IFERROR(AVERAGE(B38:D38),0) -> 403.86333 | G38: =IFERROR(AVERAGE(B38:D38),0) -> 403.86333 | H38: =IFERROR(AVERAGE(B38:D38),0) -> 403.86333 | I38: =IFERROR(AVERAGE(B38:D38),0) -> 403.86333 | J38: =IFERROR(AVERAGE(B38:D38),0) -> 403.86333 | K38: =IFERROR(AVERAGE(B38:D38),0) -> 403.86333 | L38: =IFERROR(AVERAGE(B38:D38),0) -> 403.86333 | M38: =IFERROR(AVERAGE(B38:D38),0) -> 403.86333 | N38: =SUM(B38:M38) -> 4675.7967 | O38: Média Jan-Mar
A39: 60083-TRANSPORTES E FRETES | B39: 957.55 | C39: 1679.83 | D39: 1000.46 | E39: 1480.37 | F39: =IFERROR(AVERAGE(B39:D39),0) -> 1212.6133 | G39: =IFERROR(AVERAGE(B39:D39),0) -> 1212.6133 | H39: =IFERROR(AVERAGE(B39:D39),0) -> 1212.6133 | I39: =IFERROR(AVERAGE(B39:D39),0) -> 1212.6133 | J39: =IFERROR(AVERAGE(B39:D39),0) -> 1212.6133 | K39: =IFERROR(AVERAGE(B39:D39),0) -> 1212.6133 | L39: =IFERROR(AVERAGE(B39:D39),0) -> 1212.6133 | M39: =IFERROR(AVERAGE(B39:D39),0) -> 1212.6133 | N39: =SUM(B39:M39) -> 14819.117 | O39: Média Jan-Mar
A40: 60081-SERVICO TECNOLOGIA DA INFORMACAO | B40: 900 | C40: 900 | D40: 900 | E40: 900 | F40: =IFERROR(AVERAGE(B40:D40),0) -> 900 | G40: =IFERROR(AVERAGE(B40:D40),0) -> 900 | H40: =IFERROR(AVERAGE(B40:D40),0) -> 900 | I40: =IFERROR(AVERAGE(B40:D40),0) -> 900 | J40: =IFERROR(AVERAGE(B40:D40),0) -> 900 | K40: =IFERROR(AVERAGE(B40:D40),0) -> 900 | L40: =IFERROR(AVERAGE(B40:D40),0) -> 900 | M40: =IFERROR(AVERAGE(B40:D40),0) -> 900 | N40: =SUM(B40:M40) -> 10800 | O40: Valor Fixo
...

Sheet Gastos com a Franqueadora
A1: GASTOS COM A FRANQUEADORA - EVOLUÇÃO 2026
A4: Despesa | B4: Jan | C4: Fev | D4: Mar | E4: Abr | F4: Mai | G4: TOTAL 2026
A5: 60052-ROYALTIES | B5: =SUMIFS(BASE!$K:$K,BASE!$C:$C,$A5,BASE!$M:$M,2026,BASE!$D:$D,"01/2026") -> 2623.02 | C5: =SUMIFS(BASE!$K:$K,BASE!$C:$C,$A5,BASE!$M:$M,2026,BASE!$D:$D,"02/2026") -> 24839.94 | D5: =SUMIFS(BASE!$K:$K,BASE!$C:$C,$A5,BASE!$M:$M,2026,BASE!$D:$D,"03/2026") -> 20571.58 | E5: =SUMIFS(BASE!$K:$K,BASE!$C:$C,$A5,BASE!$M:$M,2026,BASE!$D:$D,"04/2026") -> 26432.78 | F5: =SUMIFS(BASE!$K:$K,BASE!$C:$C,$A5,BASE!$M:$M,2026,BASE!$D:$D,"05/2026") -> 24737.21 | G5: =SUM(B5:F5) -> 99204.53
A6: 60001-APOSTILA | B6: =SUMIFS(BASE!$K:$K,BASE!$C:$C,$A6,BASE!$M:$M,2026,BASE!$D:$D,"01/2026") -> 0 | C6: =SUMIFS(BASE!$K:$K,BASE!$C:$C,$A6,BASE!$M:$M,2026,BASE!$D:$D,"02/2026") -> 3152.57 | D6: =SUMIFS(BASE!$K:$K,BASE!$C:$C,$A6,BASE!$M:$M,2026,BASE!$D:$D,"03/2026") -> 1993.52 | E6: =SUMIFS(BASE!$K:$K,BASE!$C:$C,$A6,BASE!$M:$M,2026,BASE!$D:$D,"04/2026") -> 15622.75 | F6: =SUMIFS(BASE!$K:$K,BASE!$C:$C,$A6,BASE!$M:$M,2026,BASE!$D:$D,"05/2026") -> 3992.8 | G6: =SUM(B6:F6) -> 24761.64
A7: 60053-FUNDO DE PROPAGANDA | B7: =SUMIFS(BASE!$K:$K,BASE!$C:$C,$A7,BASE!$M:$M,2026,BASE!$D:$D,"01/2026") -> 11568.26 | C7: =SUMIFS(BASE!$K:$K,BASE!$C:$C,$A7,BASE!$M:$M,2026,BASE!$D:$D,"02/2026") -> 11802.77 | D7: =SUMIFS(BASE!$K:$K,BASE!$C:$C,$A7,BASE!$M:$M,2026,BASE!$D:$D,"03/2026") -> 12392.42 | E7: =SUMIFS(BASE!$K:$K,BASE!$C:$C,$A7,BASE!$M:$M,2026,BASE!$D:$D,"04/2026") -> 9304.76 | F7: =SUMIFS(BASE!$K:$K,BASE!$C:$C,$A7,BASE!$M:$M,2026,BASE!$D:$D,"05/2026") -> 13742.91 | G7: =SUM(B7:F7) -> 58811.12
A8: TOTAL FRANQUEADORA | B8: =SUM(B5:B7) -> 14191.28 | C8: =SUM(C5:C7) -> 39795.28 | D8: =SUM(D5:D7) -> 34957.52 | E8: =SUM(E5:E7) -> 51360.29 | F8: =SUM(F5:F7) -> 42472.92 | G8: =SUM(G5:G7) -> 182777.29
A10: TOTAL GERAL DESPESAS | B10: =DIN_TAXA!C121 -> 311536.31 | C10: =DIN_TAXA!D121 -> 327176.73 | D10: =DIN_TAXA!E121 -> 332050.92 | E10: =DIN_TAXA!F121 -> 366849.77 | F10: =DIN_TAXA!G121 -> 333682.87 | G10: =DIN_TAXA!H121 -> 1671296.6
A12: % REPRESENTATIVIDADE | B12: =IF(B10=0,0,B8/B10) -> 0.045552571 | C12: =IF(C10=0,0,C8/C10) -> 0.12163237 | D12: =IF(D10=0,0,D8/D10) -> 0.10527759 | E12: =IF(E10=0,0,E8/E10) -> 0.1400036 | F12: =IF(F10=0,0,F8/F10) -> 0.12728529 | G12: =IF(G10=0,0,G8/G10) -> 0.10936257
A14: % REPRESENTATIVIDADE POR DESPESA
A15: 60052-ROYALTIES | B15: =IF(B$10=0,0,B5/B$10) -> 0.0084196285 | C15: =IF(C$10=0,0,C5/C$10) -> 0.075922087 | D15: =IF(D$10=0,0,D5/D$10) -> 0.061953088 | E15: =IF(E$10=0,0,E5/E$10) -> 0.072053418 | F15: =IF(F$10=0,0,F5/F$10) -> 0.074133892 | G15: =IF(G$10=0,0,G5/G$10) -> 0.059357824
A16: 60001-APOSTILA | B16: =IF(B$10=0,0,B6/B$10) -> 0 | C16: =IF(C$10=0,0,C6/C$10) -> 0.0096356792 | D16: =IF(D$10=0,0,D6/D$10) -> 0.0060036575 | E16: =IF(E$10=0,0,E6/E$10) -> 0.042586234 | F16: =IF(F$10=0,0,F6/F$10) -> 0.011965852 | G16: =IF(G$10=0,0,G6/G$10) -> 0.014815826
A17: 60053-FUNDO DE PROPAGANDA | B17: =IF(B$10=0,0,B7/B$10) -> 0.037132943 | C17: =IF(C$10=0,0,C7/C$10) -> 0.036074601 | D17: =IF(D$10=0,0,D7/D$10) -> 0.037320842 | E17: =IF(E$10=0,0,E7/E$10) -> 0.025363952 | F17: =IF(F$10=0,0,F7/F$10) -> 0.041185542 | G17: =IF(G$10=0,0,G7/G$10) -> 0.035188919
A20: DADOS PARA GRÁFICO (EVOLUÇÃO MENSAL)
A21: Despesa | B21: 46048 | C21: Fev/26 | D21: 46107 | E21: Abr/26 | F21: Mai/26
A22: 60052-ROYALTIES | B22: =B5 -> 2623.02 | C22: =C5 -> 24839.94 | D22: =D5 -> 20571.58 | E22: =E5 -> 26432.78 | F22: =F5 -> 24737.21
A23: 60001-APOSTILA | B23: =B6 -> 0 | C23: =C6 -> 3152.57 | D23: =D6 -> 1993.52 | E23: =E6 -> 15622.75 | F23: =F6 -> 3992.8
A24: 60053-FUNDO DE PROPAGANDA | B24: =B7 -> 11568.26 | C24: =C7 -> 11802.77 | D24: =D7 -> 12392.42 | E24: =E7 -> 9304.76 | F24: =F7 -> 13742.91
A25: % REPRESENTATIVIDADE | B25: =B12 -> 0.045552571 | C25: =C12 -> 0.12163237 | D25: =D12 -> 0.10527759 | E25: =E12 -> 0.1400036 | F25: =F12 -> 0.12728529
A66: 📊 RESUMO ESTATÍSTICO - 2026
A67: Despesa | B67: Total 2026 | C67: Média Mensal | D67: % do Total Franq. | E67: % do Total Geral
A68: 60052-ROYALTIES | B68: =G5 -> 99204.53 | C68: =G5/5 -> 19840.906 | D68: =IF(G8=0,0,G5/G8) -> 0.54276179 | E68: =IF(G10=0,0,G5/G10) -> 0.059357824
A69: 60001-APOSTILA | B69: =G6 -> 24761.64 | C69: =G6/5 -> 4952.328 | D69: =IF(G8=0,0,G6/G8) -> 0.13547438 | E69: =IF(G10=0,0,G6/G10) -> 0.014815826
A70: 60053-FUNDO DE PROPAGANDA | B70: =G7 -> 58811.12 | C70: =G7/5 -> 11762.224 | D70: =IF(G8=0,0,G7/G8) -> 0.32176383 | E70: =IF(G10=0,0,G7/G10) -> 0.035188919
A71: TOTAL FRANQUEADORA | B71: =G8 -> 182777.29 | C71: =G8/5 -> 36555.458 | D71: =IF(G8=0,0,1) -> 1 | E71: =IF(G10=0,0,G8/G10) -> 0.10936257
A73: 🔄 ATUALIZAÇÃO AUTOMÁTICA
A74: Todos os dados desta planilha estão vinculados à BASE e serão atualizados automaticamente.
